<?xml version="1.0" encoding="utf-8"?>
<!-- This URDF was automatically created by SolidWorks to URDF Exporter! Originally created by Stephen Brawner (brawner@gmail.com) 
     Commit Version: 1.6.0-4-g7f85cfe  Build Version: 1.6.7995.38578
     For more information, please see http://wiki.ros.org/sw_urdf_exporter -->
<robot
  name="flagship_mec_bs_robot">
  <link
    name="base_link">
    <inertial>
      <origin
        xyz="0.00711629652434545 -0.00322188502370258 0.0164854811219013"
        rpy="0 0 0" />
      <mass
        value="5.76365762403607" />
      <inertia
        ixx="0.0600889108992141"
        ixy="3.87485100856728E-05"
        ixz="-1.84300048840965E-05"
        iyy="0.0471196307889214"
        iyz="-2.87955340141594E-06"
        izz="0.103264644876046" />
    </inertial>
    <visual>
      <origin
        xyz="0 0 0"
        rpy="0 0 0" />
      <geometry>
        <mesh
          filename="package://wheeltec_robot_urdf/meshes/flagship_mec_bs_robot_meshes/base_link.STL" />
      </geometry>
      <material
        name="">
        <color
          rgba="0.741176470588235 0.901960784313726 0.956862745098039 1" />
      </material>
    </visual>
    <collision>
      <origin
        xyz="0 0 0"
        rpy="0 0 0" />
      <geometry>
        <mesh
          filename="package://wheeltec_robot_urdf/meshes/flagship_mec_bs_robot_meshes/base_link.STL" />
      </geometry>
    </collision>
  </link>
  <link
    name="lf_wheel_link">
    <inertial>
      <origin
        xyz="1.31767780936487E-07 -0.00248009071711623 -1.69865789075019E-06"
        rpy="0 0 0" />
      <mass
        value="0.242468456480216" />
      <inertia
        ixx="0.000457067612620108"
        ixy="-2.37655732307157E-07"
        ixz="3.85301516879172E-09"
        iyy="0.000868087814770307"
        iyz="-1.59350892256097E-09"
        izz="0.000456505782058785" />
    </inertial>
    <visual>
      <origin
        xyz="0 0 0"
        rpy="0 0 0" />
      <geometry>
        <mesh
          filename="package://wheeltec_robot_urdf/meshes/flagship_mec_bs_robot_meshes/lf_wheel_link.STL" />
      </geometry>
      <material
        name="">
        <color
          rgba="1 1 1 1" />
      </material>
    </visual>
    <collision>
      <origin
        xyz="0 0 0"
        rpy="0 0 0" />
      <geometry>
        <mesh
          filename="package://wheeltec_robot_urdf/meshes/flagship_mec_bs_robot_meshes/lf_wheel_link.STL" />
      </geometry>
    </collision>
  </link>
  <joint
    name="lf_wheel_joint"
    type="continuous">
    <origin
      xyz="0.185693160645845 0.291475641802976 -0.037493999999996"
      rpy="0 0 0" />
    <parent
      link="base_link" />
    <child
      link="lf_wheel_link" />
    <axis
      xyz="0 1 0" />
  </joint>
  <link
    name="lb_wheel_link">
    <inertial>
      <origin
        xyz="1.31767767641566E-07 -0.00248009071710622 -1.69865775480338E-06"
        rpy="0 0 0" />
      <mass
        value="0.24246845648113" />
      <inertia
        ixx="0.000457067612621628"
        ixy="-2.37655732773179E-07"
        ixz="3.85301527571913E-09"
        iyy="0.00086808781477231"
        iyz="-1.59350893040512E-09"
        izz="0.00045650578205984" />
    </inertial>
    <visual>
      <origin
        xyz="0 0 0"
        rpy="0 0 0" />
      <geometry>
        <mesh
          filename="package://wheeltec_robot_urdf/meshes/flagship_mec_bs_robot_meshes/lb_wheel_link.STL" />
      </geometry>
      <material
        name="">
        <color
          rgba="1 1 1 1" />
      </material>
    </visual>
    <collision>
      <origin
        xyz="0 0 0"
        rpy="0 0 0" />
      <geometry>
        <mesh
          filename="package://wheeltec_robot_urdf/meshes/flagship_mec_bs_robot_meshes/lb_wheel_link.STL" />
      </geometry>
    </collision>
  </link>
  <joint
    name="lb_wheel_joint"
    type="continuous">
    <origin
      xyz="-0.168006839354155 0.291475641802975 -0.037493999999996"
      rpy="0 0 0" />
    <parent
      link="base_link" />
    <child
      link="lb_wheel_link" />
    <axis
      xyz="0 1 0" />
  </joint>
  <link
    name="rb_wheel_link">
    <inertial>
      <origin
        xyz="-1.31767769306901E-07 0.00248009071710664 -1.69865775746791E-06"
        rpy="0 0 0" />
      <mass
        value="0.242468456481127" />
      <inertia
        ixx="0.000457067612621629"
        ixy="-2.37655732772187E-07"
        ixz="-3.85301527540644E-09"
        iyy="0.000868087814772308"
        iyz="1.59350893244824E-09"
        izz="0.000456505782059837" />
    </inertial>
    <visual>
      <origin
        xyz="0 0 0"
        rpy="0 0 0" />
      <geometry>
        <mesh
          filename="package://wheeltec_robot_urdf/meshes/flagship_mec_bs_robot_meshes/rb_wheel_link.STL" />
      </geometry>
      <material
        name="">
        <color
          rgba="0.741176470588235 0.901960784313726 0.956862745098039 1" />
      </material>
    </visual>
    <collision>
      <origin
        xyz="0 0 0"
        rpy="0 0 0" />
      <geometry>
        <mesh
          filename="package://wheeltec_robot_urdf/meshes/flagship_mec_bs_robot_meshes/rb_wheel_link.STL" />
      </geometry>
    </collision>
  </link>
  <joint
    name="rb_wheel_joint"
    type="continuous">
    <origin
      xyz="-0.168006839354153 -0.290440358197025 -0.037493999999994"
      rpy="0 0 0" />
    <parent
      link="base_link" />
    <child
      link="rb_wheel_link" />
    <axis
      xyz="0 -1 0" />
  </joint>
  <link
    name="rf_wheel_link">
    <inertial>
      <origin
        xyz="-1.31767768529745E-07 0.00248009071710642 -1.69865775660749E-06"
        rpy="0 0 0" />
      <mass
        value="0.242468456481129" />
      <inertia
        ixx="0.000457067612621626"
        ixy="-2.37655732773136E-07"
        ixz="-3.85301527388279E-09"
        iyy="0.000868087814772302"
        iyz="1.59350892876556E-09"
        izz="0.000456505782059834" />
    </inertial>
    <visual>
      <origin
        xyz="0 0 0"
        rpy="0 0 0" />
      <geometry>
        <mesh
          filename="package://wheeltec_robot_urdf/meshes/flagship_mec_bs_robot_meshes/rf_wheel_link.STL" />
      </geometry>
      <material
        name="">
        <color
          rgba="0.741176470588235 0.901960784313726 0.956862745098039 1" />
      </material>
    </visual>
    <collision>
      <origin
        xyz="0 0 0"
        rpy="0 0 0" />
      <geometry>
        <mesh
          filename="package://wheeltec_robot_urdf/meshes/flagship_mec_bs_robot_meshes/rf_wheel_link.STL" />
      </geometry>
    </collision>
  </link>
  <joint
    name="rf_wheel_joint"
    type="continuous">
    <origin
      xyz="0.185693160645847 -0.291440358197024 -0.037493999999994"
      rpy="0 0 0" />
    <parent
      link="base_link" />
    <child
      link="rf_wheel_link" />
    <axis
      xyz="0 -1 0" />
  </joint>
  <link
    name="camera_link">
    <inertial>
      <origin
        xyz="-1.4947234060203E-07 1.57376155773825E-07 -3.19615127988837E-07"
        rpy="0 0 0" />
      <mass
        value="0.0559842529202771" />
      <inertia
        ixx="0.000130802200744622"
        ixy="-9.9661745303399E-07"
        ixz="1.62299342697035E-06"
        iyy="1.9123626272978E-05"
        iyz="-4.42334063841986E-08"
        izz="0.000131387473459422" />
    </inertial>
    <visual>
      <origin
        xyz="0 0 0"
        rpy="0 0 0" />
      <geometry>
        <mesh
          filename="package://wheeltec_robot_urdf/meshes/flagship_mec_bs_robot_meshes/camera_link.STL" />
      </geometry>
      <material
        name="">
        <color
          rgba="1 1 1 1" />
      </material>
    </visual>
    <collision>
      <origin
        xyz="0 0 0"
        rpy="0 0 0" />
      <geometry>
        <mesh
          filename="package://wheeltec_robot_urdf/meshes/flagship_mec_bs_robot_meshes/camera_link.STL" />
      </geometry>
    </collision>
  </link>
  <joint
    name="camera_joint"
    type="fixed">
    <origin
      xyz="0.298787160645846 0.000240641802977198 0.172196000000005"
      rpy="0 0 0" />
    <parent
      link="base_link" />
    <child
      link="camera_link" />
    <axis
      xyz="0 0 0" />
  </joint>
  <link
    name="laser_link">
    <inertial>
      <origin
        xyz="-0.00207956288634139 -9.87028646648458E-07 -0.0264472435671745"
        rpy="0 0 0" />
      <mass
        value="0.00426368606026273" />
      <inertia
        ixx="1.45373992961576E-06"
        ixy="2.48436941244439E-14"
        ixz="-8.86181044864495E-08"
        iyy="1.1764772028955E-06"
        iyz="-2.28919961124084E-15"
        izz="2.0383666687487E-06" />
    </inertial>
    <visual>
      <origin
        xyz="0 0 0"
        rpy="0 0 0" />
      <geometry>
        <mesh
          filename="package://wheeltec_robot_urdf/meshes/flagship_mec_bs_robot_meshes/laser.STL" />
      </geometry>
      <material
        name="">
        <color
          rgba="0.376470588235294 0.376470588235294 0.376470588235294 1" />
      </material>
    </visual>
    <collision>
      <origin
        xyz="0 0 0"
        rpy="0 0 0" />
      <geometry>
        <mesh
          filename="package://wheeltec_robot_urdf/meshes/flagship_mec_bs_robot_meshes/laser.STL" />
      </geometry>
    </collision>
  </link>
  <joint
    name="laser_joint"
    type="fixed">
    <origin
      xyz="0.246992160645846 1.66418029772797E-05 0.244656000000005"
      rpy="0 0 -3.14159265358979" />
    <parent
      link="base_link" />
    <child
      link="laser_link" />
    <axis
      xyz="0 0 0" />
  </joint>
  <link
    name="controller_link">
    <inertial>
      <origin
        xyz="-0.0497103400547848 0.017513393269055 0.00856001464881975"
        rpy="0 0 0" />
      <mass
        value="0.0010792195411469" />
      <inertia
        ixx="1.16330109995672E-08"
        ixy="-3.9409266251513E-09"
        ixz="3.69212982720481E-10"
        iyy="2.26830021861923E-07"
        iyz="5.23015112085348E-10"
        izz="2.25657044103424E-07" />
    </inertial>
    <visual>
      <origin
        xyz="0 0 0"
        rpy="0 0 0" />
      <geometry>
        <mesh
          filename="package://wheeltec_robot_urdf/meshes/flagship_mec_bs_robot_meshes/controller_link.STL" />
      </geometry>
      <material
        name="">
        <color
          rgba="0.741176470588235 0.901960784313726 0.956862745098039 1" />
      </material>
    </visual>
    <collision>
      <origin
        xyz="0 0 0"
        rpy="0 0 0" />
      <geometry>
        <mesh
          filename="package://wheeltec_robot_urdf/meshes/flagship_mec_bs_robot_meshes/controller_link.STL" />
      </geometry>
    </collision>
  </link>
  <joint
    name="controller_joint"
    type="fixed">
    <origin
      xyz="0.101379911991688 0.0620176418028518 0.00150000000000057"
      rpy="0 0 0" />
    <parent
      link="base_link" />
    <child
      link="controller_link" />
    <axis
      xyz="0 0 0" />
  </joint>
</robot>
