<?xml version="1.0" encoding="utf-8"?>
<!-- This URDF was automatically created by SolidWorks to URDF Exporter! Originally created by Stephen Brawner (brawner@gmail.com) 
     Commit Version: 1.6.0-4-g7f85cfe  Build Version: 1.6.7995.38578
     For more information, please see http://wiki.ros.org/sw_urdf_exporter -->
<robot
  name="flagship_mec_dl_robot">
  <link
    name="base_link">
    <inertial>
      <origin
        xyz="0.00594974838644888 -0.00278208830712817 0.0722012306894268"
        rpy="0 0 0" />
      <mass
        value="6.62656507613353" />
      <inertia
        ixx="0.0570575550370139"
        ixy="3.97387433819612E-05"
        ixz="-1.84274067462165E-05"
        iyy="0.051379871182729"
        iyz="-2.86896780013599E-06"
        izz="0.100906419214713" />
    </inertial>
    <visual>
      <origin
        xyz="0 0 0"
        rpy="0 0 0" />
      <geometry>
        <mesh
          filename="package://wheeltec_robot_urdf/meshes/flagship_mec_dl_robot_meshes/base_link.STL" />
      </geometry>
      <material
        name="">
        <color
          rgba="0.741176470588235 0.901960784313726 0.956862745098039 1" />
      </material>
    </visual>
    <collision>
      <origin
        xyz="0 0 0"
        rpy="0 0 0" />
      <geometry>
        <mesh
          filename="package://wheeltec_robot_urdf/meshes/flagship_mec_dl_robot_meshes/base_link.STL" />
      </geometry>
    </collision>
  </link>
  <link
    name="lf_wheel_link">
    <inertial>
      <origin
        xyz="-1.70957566257568E-06 -0.0025314415859214 -2.79377279116533E-07"
        rpy="0 0 0" />
      <mass
        value="0.242468136040734" />
      <inertia
        ixx="0.000456509780047165"
        ixy="2.48764554444717E-08"
        ixz="5.85963433566155E-08"
        iyy="0.000868083348561862"
        iyz="2.36373884719179E-07"
        izz="0.000457059209008134" />
    </inertial>
    <visual>
      <origin
        xyz="0 0 0"
        rpy="0 0 0" />
      <geometry>
        <mesh
          filename="package://wheeltec_robot_urdf/meshes/flagship_mec_dl_robot_meshes/lf_wheel_link.STL" />
      </geometry>
      <material
        name="">
        <color
          rgba="0.741176470588235 0.901960784313726 0.956862745098039 1" />
      </material>
    </visual>
    <collision>
      <origin
        xyz="0 0 0"
        rpy="0 0 0" />
      <geometry>
        <mesh
          filename="package://wheeltec_robot_urdf/meshes/flagship_mec_dl_robot_meshes/lf_wheel_link.STL" />
      </geometry>
    </collision>
  </link>
  <joint
    name="lf_wheel_joint"
    type="continuous">
    <origin
      xyz="0.174353547464883 0.287671641802973 0.0364999999999989"
      rpy="0 0 0" />
    <parent
      link="base_link" />
    <child
      link="lf_wheel_link" />
    <axis
      xyz="0 -1 0" />
  </joint>
  <link
    name="lb_wheel_link">
    <inertial>
      <origin
        xyz="-1.28245085789791E-06 -0.00253144158593806 -2.79377288775473E-07"
        rpy="0 0 0" />
      <mass
        value="0.242468136040723" />
      <inertia
        ixx="0.000456509780047214"
        ixy="2.48764554418041E-08"
        ixz="5.85963434144802E-08"
        iyy="0.000868083348561837"
        iyz="2.36373884663941E-07"
        izz="0.000457059209008281" />
    </inertial>
    <visual>
      <origin
        xyz="0 0 0"
        rpy="0 0 0" />
      <geometry>
        <mesh
          filename="package://wheeltec_robot_urdf/meshes/flagship_mec_dl_robot_meshes/lb_wheel_link.STL" />
      </geometry>
      <material
        name="">
        <color
          rgba="0.741176470588235 0.901960784313726 0.956862745098039 1" />
      </material>
    </visual>
    <collision>
      <origin
        xyz="0 0 0"
        rpy="0 0 0" />
      <geometry>
        <mesh
          filename="package://wheeltec_robot_urdf/meshes/flagship_mec_dl_robot_meshes/lb_wheel_link.STL" />
      </geometry>
    </collision>
  </link>
  <joint
    name="lb_wheel_joint"
    type="continuous">
    <origin
      xyz="-0.175638452535117 0.287671641802972 0.0364999999999989"
      rpy="0 0 0" />
    <parent
      link="base_link" />
    <child
      link="lb_wheel_link" />
    <axis
      xyz="0 -1 0" />
  </joint>
  <link
    name="rb_wheel_link">
    <inertial>
      <origin
        xyz="1.28231328827555E-06 0.00253144151010509 -2.7917555672774E-07"
        rpy="0 0 0" />
      <mass
        value="0.242468138567029" />
      <inertia
        ixx="0.000456509782277566"
        ixy="2.48771202902957E-08"
        ixz="-5.85954248573733E-08"
        iyy="0.000868083350535182"
        iyz="-2.36374859176783E-07"
        izz="0.000457059210518107" />
    </inertial>
    <visual>
      <origin
        xyz="0 0 0"
        rpy="0 0 0" />
      <geometry>
        <mesh
          filename="package://wheeltec_robot_urdf/meshes/flagship_mec_dl_robot_meshes/rb_wheel_link.STL" />
      </geometry>
      <material
        name="">
        <color
          rgba="0.741176470588235 0.901960784313726 0.956862745098039 1" />
      </material>
    </visual>
    <collision>
      <origin
        xyz="0 0 0"
        rpy="0 0 0" />
      <geometry>
        <mesh
          filename="package://wheeltec_robot_urdf/meshes/flagship_mec_dl_robot_meshes/rb_wheel_link.STL" />
      </geometry>
    </collision>
  </link>
  <joint
    name="rb_wheel_joint"
    type="continuous">
    <origin
      xyz="-0.177666452535115 -0.287636358197028 0.0365000000000009"
      rpy="0 0 0" />
    <parent
      link="base_link" />
    <child
      link="rb_wheel_link" />
    <axis
      xyz="0 1 0" />
  </joint>
  <link
    name="rf_wheel_link">
    <inertial>
      <origin
        xyz="1.70943808744384E-06 0.00253144151010598 -2.79175556075484E-07"
        rpy="0 0 0" />
      <mass
        value="0.242468138567038" />
      <inertia
        ixx="0.000456509782277578"
        ixy="2.48771202905662E-08"
        ixz="-5.85954248588823E-08"
        iyy="0.000868083350535201"
        iyz="-2.36374859176799E-07"
        izz="0.000457059210518115" />
    </inertial>
    <visual>
      <origin
        xyz="0 0 0"
        rpy="0 0 0" />
      <geometry>
        <mesh
          filename="package://wheeltec_robot_urdf/meshes/flagship_mec_dl_robot_meshes/rf_wheel_link.STL" />
      </geometry>
      <material
        name="">
        <color
          rgba="0.741176470588235 0.901960784313726 0.956862745098039 1" />
      </material>
    </visual>
    <collision>
      <origin
        xyz="0 0 0"
        rpy="0 0 0" />
      <geometry>
        <mesh
          filename="package://wheeltec_robot_urdf/meshes/flagship_mec_dl_robot_meshes/rf_wheel_link.STL" />
      </geometry>
    </collision>
  </link>
  <joint
    name="rf_wheel_joint"
    type="continuous">
    <origin
      xyz="0.174341547464885 -0.287636358197027 0.0365000000000009"
      rpy="0 0 0" />
    <parent
      link="base_link" />
    <child
      link="rf_wheel_link" />
    <axis
      xyz="0 1 0" />
  </joint>
  <link
    name="camera_link">
    <inertial>
      <origin
        xyz="-1.49472333864364E-07 1.57376157022826E-07 1.07509871657974E-07"
        rpy="0 0 0" />
      <mass
        value="0.0559842529202529" />
      <inertia
        ixx="0.000130802200744606"
        ixy="-9.96617453030928E-07"
        ixz="1.6229934269714E-06"
        iyy="1.91236262729695E-05"
        iyz="-4.42334063852427E-08"
        izz="0.000131387473459401" />
    </inertial>
    <visual>
      <origin
        xyz="0 0 0"
        rpy="0 0 0" />
      <geometry>
        <mesh
          filename="package://wheeltec_robot_urdf/meshes/flagship_mec_dl_robot_meshes/camera_link.STL" />
      </geometry>
      <material
        name="">
        <color
          rgba="1 1 1 1" />
      </material>
    </visual>
    <collision>
      <origin
        xyz="0 0 0"
        rpy="0 0 0" />
      <geometry>
        <mesh
          filename="package://wheeltec_robot_urdf/meshes/flagship_mec_dl_robot_meshes/camera_link.STL" />
      </geometry>
    </collision>
  </link>
  <joint
    name="camera_joint"
    type="fixed">
    <origin
      xyz="0.290141547464884 0.000240641802974284 0.212204"
      rpy="0 0 0" />
    <parent
      link="base_link" />
    <child
      link="camera_link" />
    <axis
      xyz="0 0 0" />
  </joint>
  <link
    name="laser_link">
    <inertial>
      <origin
        xyz="-0.00207956288634146 -9.87028646426413E-07 -0.0264468164421749"
        rpy="0 0 0" />
      <mass
        value="0.0042636860602628" />
      <inertia
        ixx="1.45373992961578E-06"
        ixy="2.48436940399223E-14"
        ixz="-8.86181044864521E-08"
        iyy="1.17647720289552E-06"
        iyz="-2.28919823518326E-15"
        izz="2.03836666874872E-06" />
    </inertial>
    <visual>
      <origin
        xyz="0 0 0"
        rpy="0 0 0" />
      <geometry>
        <mesh
          filename="package://wheeltec_robot_urdf/meshes/flagship_mec_dl_robot_meshes/laser.STL" />
      </geometry>
      <material
        name="">
        <color
          rgba="0.376470588235294 0.376470588235294 0.376470588235294 1" />
      </material>
    </visual>
    <collision>
      <origin
        xyz="0 0 0"
        rpy="0 0 0" />
      <geometry>
        <mesh
          filename="package://wheeltec_robot_urdf/meshes/flagship_mec_dl_robot_meshes/laser.STL" />
      </geometry>
    </collision>
  </link>
  <joint
    name="laser_joint"
    type="fixed">
    <origin
      xyz="0.238346547464884 1.66418029743376E-05 0.284664"
      rpy="0 0 -3.14159265358979" />
    <parent
      link="base_link" />
    <child
      link="laser_link" />
    <axis
      xyz="0 0 0" />
  </joint>
  <link
    name="controller_link">
    <inertial>
      <origin
        xyz="-0.0497103400790867 0.0175133935293348 0.00856001460559355"
        rpy="0 0 0" />
      <mass
        value="0.00107921953110441" />
      <inertia
        ixx="1.16330109775188E-08"
        ixy="-3.94092668869787E-09"
        ixz="3.69212784612797E-10"
        iyy="2.26830020206362E-07"
        iyz="5.23015130069641E-10"
        izz="2.25657042461949E-07" />
    </inertial>
    <visual>
      <origin
        xyz="0 0 0"
        rpy="0 0 0" />
      <geometry>
        <mesh
          filename="package://wheeltec_robot_urdf/meshes/flagship_mec_dl_robot_meshes/controller_link.STL" />
      </geometry>
      <material
        name="">
        <color
          rgba="0.741176470588235 0.901960784313726 0.956862745098039 1" />
      </material>
    </visual>
    <collision>
      <origin
        xyz="0 0 0"
        rpy="0 0 0" />
      <geometry>
        <mesh
          filename="package://wheeltec_robot_urdf/meshes/flagship_mec_dl_robot_meshes/controller_link.STL" />
      </geometry>
    </collision>
  </link>
  <joint
    name="controller_joint"
    type="fixed">
    <origin
      xyz="0.101379911991688 0.0620176418028517 0.00150000000000053"
      rpy="0 0 0" />
    <parent
      link="base_link" />
    <child
      link="controller_link" />
    <axis
      xyz="0 0 0" />
  </joint>
</robot>
