<?xml version="1.0" encoding="utf-8"?>
<!-- This URDF was automatically created by SolidWorks to URDF Exporter! Originally created by Stephen Brawner (brawner@gmail.com) 
     Commit Version: 1.6.0-4-g7f85cfe  Build Version: 1.6.7995.38578
     For more information, please see http://wiki.ros.org/sw_urdf_exporter -->
<robot
  name="four_wheel_diff_dl_robot">
  <link
    name="base_link">
    <inertial>
      <origin
        xyz="0.0318457355753914 -0.00318231456734142 0.0771658331837553"
        rpy="0 0 0" />
      <mass
        value="5.79776460892104" />
      <inertia
        ixx="0.0481292435780642"
        ixy="-2.4203123053616E-05"
        ixz="-1.84274070905059E-05"
        iyy="0.049082492083211"
        iyz="-2.86896746900882E-06"
        izz="0.0909825416633626" />
    </inertial>
    <visual>
      <origin
        xyz="0 0 0"
        rpy="0 0 0" />
      <geometry>
        <mesh
          filename="package://wheeltec_robot_urdf/meshes/four_wheel_diff_dl_robot_meshes/base_link.STL" />
      </geometry>
      <material
        name="">
        <color
          rgba="0.741176470588235 0.901960784313726 0.956862745098039 1" />
      </material>
    </visual>
    <collision>
      <origin
        xyz="0 0 0"
        rpy="0 0 0" />
      <geometry>
        <mesh
          filename="package://wheeltec_robot_urdf/meshes/four_wheel_diff_dl_robot_meshes/base_link.STL" />
      </geometry>
    </collision>
  </link>
  <link
    name="lf_wheel_link">
    <inertial>
      <origin
        xyz="-1.81859304254628E-07 -0.00226980673596285 7.20735205350653E-07"
        rpy="0 0 0" />
      <mass
        value="0.59173319478051" />
      <inertia
        ixx="0.00187537173700357"
        ixy="1.48463879375619E-08"
        ixz="-5.9953347590458E-08"
        iyy="0.00345081841864374"
        iyz="-5.13834909176119E-08"
        izz="0.00187556225815756" />
    </inertial>
    <visual>
      <origin
        xyz="0 0 0"
        rpy="0 0 0" />
      <geometry>
        <mesh
          filename="package://wheeltec_robot_urdf/meshes/four_wheel_diff_dl_robot_meshes/lf_wheel_link.STL" />
      </geometry>
      <material
        name="">
        <color
          rgba="0.741176470588235 0.901960784313726 0.956862745098039 1" />
      </material>
    </visual>
    <collision>
      <origin
        xyz="0 0 0"
        rpy="0 0 0" />
      <geometry>
        <mesh
          filename="package://wheeltec_robot_urdf/meshes/four_wheel_diff_dl_robot_meshes/lf_wheel_link.STL" />
      </geometry>
    </collision>
  </link>
  <joint
    name="lf_wheel_joint"
    type="continuous">
    <origin
      xyz="0.174358547464883 0.295582641802973 0.0364909999999989"
      rpy="0 0 0" />
    <parent
      link="base_link" />
    <child
      link="lf_wheel_link" />
    <axis
      xyz="0 1 0" />
  </joint>
  <link
    name="lb_wheel_link">
    <inertial>
      <origin
        xyz="-4.36645918699963E-07 -0.00504700490176194 -6.46755826672063E-09"
        rpy="0 0 0" />
      <mass
        value="0.420612332565552" />
      <inertia
        ixx="0.00119912339307498"
        ixy="-1.39093157978753E-10"
        ixz="-1.42791089130004E-10"
        iyy="0.00231233093777319"
        iyz="-8.94581194667738E-11"
        izz="0.0011991234972276" />
    </inertial>
    <visual>
      <origin
        xyz="0 0 0"
        rpy="0 0 0" />
      <geometry>
        <mesh
          filename="package://wheeltec_robot_urdf/meshes/four_wheel_diff_dl_robot_meshes/lb_wheel_link.STL" />
      </geometry>
      <material
        name="">
        <color
          rgba="1 1 1 1" />
      </material>
    </visual>
    <collision>
      <origin
        xyz="0 0 0"
        rpy="0 0 0" />
      <geometry>
        <mesh
          filename="package://wheeltec_robot_urdf/meshes/four_wheel_diff_dl_robot_meshes/lb_wheel_link.STL" />
      </geometry>
    </collision>
  </link>
  <joint
    name="lb_wheel_joint"
    type="continuous">
    <origin
      xyz="-0.177660452535117 0.306129641802972 0.0364999999999989"
      rpy="0 0 0" />
    <parent
      link="base_link" />
    <child
      link="lb_wheel_link" />
    <axis
      xyz="0 1 0" />
  </joint>
  <link
    name="rb_wheel_link">
    <inertial>
      <origin
        xyz="-4.17603560343149E-07 0.00504700490174181 -6.46755667077503E-09"
        rpy="0 0 0" />
      <mass
        value="0.420612332565537" />
      <inertia
        ixx="0.00119912339307497"
        ixy="-1.39093160955768E-10"
        ixz="1.42791100969105E-10"
        iyy="0.00231233093777312"
        iyz="8.9458115527756E-11"
        izz="0.00119912349722754" />
    </inertial>
    <visual>
      <origin
        xyz="0 0 0"
        rpy="0 0 0" />
      <geometry>
        <mesh
          filename="package://wheeltec_robot_urdf/meshes/four_wheel_diff_dl_robot_meshes/rb_wheel_link.STL" />
      </geometry>
      <material
        name="">
        <color
          rgba="1 1 1 1" />
      </material>
    </visual>
    <collision>
      <origin
        xyz="0 0 0"
        rpy="0 0 0" />
      <geometry>
        <mesh
          filename="package://wheeltec_robot_urdf/meshes/four_wheel_diff_dl_robot_meshes/rb_wheel_link.STL" />
      </geometry>
    </collision>
  </link>
  <joint
    name="rb_wheel_joint"
    type="continuous">
    <origin
      xyz="-0.177660452535115 -0.306094358197028 0.036500000000001"
      rpy="0 0 0" />
    <parent
      link="base_link" />
    <child
      link="rb_wheel_link" />
    <axis
      xyz="0 -1 0" />
  </joint>
  <link
    name="rf_wheel_link">
    <inertial>
      <origin
        xyz="3.61087833106177E-08 0.00226980673594079 7.20735208598056E-07"
        rpy="0 0 0" />
      <mass
        value="0.591733194780427" />
      <inertia
        ixx="0.00187537173700363"
        ixy="1.48463879446997E-08"
        ixz="5.99533475930548E-08"
        iyy="0.00345081841864383"
        iyz="5.13834909056724E-08"
        izz="0.00187556225815758" />
    </inertial>
    <visual>
      <origin
        xyz="0 0 0"
        rpy="0 0 0" />
      <geometry>
        <mesh
          filename="package://wheeltec_robot_urdf/meshes/four_wheel_diff_dl_robot_meshes/rf_wheel_link.STL" />
      </geometry>
      <material
        name="">
        <color
          rgba="0.741176470588235 0.901960784313726 0.956862745098039 1" />
      </material>
    </visual>
    <collision>
      <origin
        xyz="0 0 0"
        rpy="0 0 0" />
      <geometry>
        <mesh
          filename="package://wheeltec_robot_urdf/meshes/four_wheel_diff_dl_robot_meshes/rf_wheel_link.STL" />
      </geometry>
    </collision>
  </link>
  <joint
    name="rf_wheel_joint"
    type="continuous">
    <origin
      xyz="0.174353547464885 -0.295547358197027 0.036491000000001"
      rpy="0 0 0" />
    <parent
      link="base_link" />
    <child
      link="rf_wheel_link" />
    <axis
      xyz="0 -1 0" />
  </joint>
  <link
    name="camera_link">
    <inertial>
      <origin
        xyz="-1.49472333864364E-07 1.57376157022826E-07 1.07509871657974E-07"
        rpy="0 0 0" />
      <mass
        value="0.0559842529202529" />
      <inertia
        ixx="0.000130802200744606"
        ixy="-9.96617453030928E-07"
        ixz="1.6229934269714E-06"
        iyy="1.91236262729695E-05"
        iyz="-4.42334063852426E-08"
        izz="0.000131387473459401" />
    </inertial>
    <visual>
      <origin
        xyz="0 0 0"
        rpy="0 0 0" />
      <geometry>
        <mesh
          filename="package://wheeltec_robot_urdf/meshes/four_wheel_diff_dl_robot_meshes/camera_link.STL" />
      </geometry>
      <material
        name="">
        <color
          rgba="1 1 1 1" />
      </material>
    </visual>
    <collision>
      <origin
        xyz="0 0 0"
        rpy="0 0 0" />
      <geometry>
        <mesh
          filename="package://wheeltec_robot_urdf/meshes/four_wheel_diff_dl_robot_meshes/camera_link.STL" />
      </geometry>
    </collision>
  </link>
  <joint
    name="camera_joint"
    type="fixed">
    <origin
      xyz="0.290141547464884 0.000240641802974284 0.212204"
      rpy="0 0 0" />
    <parent
      link="base_link" />
    <child
      link="camera_link" />
    <axis
      xyz="0 0 0" />
  </joint>
  <link
    name="laser_link">
    <inertial>
      <origin
        xyz="-0.00207956288634146 -9.87028646426413E-07 -0.0264468164421749"
        rpy="0 0 0" />
      <mass
        value="0.0042636860602628" />
      <inertia
        ixx="1.45373992961578E-06"
        ixy="2.48436940401418E-14"
        ixz="-8.86181044864521E-08"
        iyy="1.17647720289552E-06"
        iyz="-2.28919823653199E-15"
        izz="2.03836666874872E-06" />
    </inertial>
    <visual>
      <origin
        xyz="0 0 0"
        rpy="0 0 0" />
      <geometry>
        <mesh
          filename="package://wheeltec_robot_urdf/meshes/four_wheel_diff_dl_robot_meshes/laser.STL" />
      </geometry>
      <material
        name="">
        <color
          rgba="0.376470588235294 0.376470588235294 0.376470588235294 1" />
      </material>
    </visual>
    <collision>
      <origin
        xyz="0 0 0"
        rpy="0 0 0" />
      <geometry>
        <mesh
          filename="package://wheeltec_robot_urdf/meshes/four_wheel_diff_dl_robot_meshes/laser.STL" />
      </geometry>
    </collision>
  </link>
  <joint
    name="laser_joint"
    type="fixed">
    <origin
      xyz="0.238346547464884 1.66418029743376E-05 0.284664"
      rpy="0 0 -3.14159265358979" />
    <parent
      link="base_link" />
    <child
      link="laser_link" />
    <axis
      xyz="0 0 0" />
  </joint>
  <link
    name="controller_link">
    <inertial>
      <origin
        xyz="-0.0497103400790867 0.0175133935293348 0.00856001460559357"
        rpy="0 0 0" />
      <mass
        value="0.00107921953110441" />
      <inertia
        ixx="1.16330109775188E-08"
        ixy="-3.94092668869786E-09"
        ixz="3.69212784612797E-10"
        iyy="2.26830020206362E-07"
        iyz="5.23015130069641E-10"
        izz="2.25657042461949E-07" />
    </inertial>
    <visual>
      <origin
        xyz="0 0 0"
        rpy="0 0 0" />
      <geometry>
        <mesh
          filename="package://wheeltec_robot_urdf/meshes/four_wheel_diff_dl_robot_meshes/controller_link.STL" />
      </geometry>
      <material
        name="">
        <color
          rgba="0.741176470588235 0.901960784313726 0.956862745098039 1" />
      </material>
    </visual>
    <collision>
      <origin
        xyz="0 0 0"
        rpy="0 0 0" />
      <geometry>
        <mesh
          filename="package://wheeltec_robot_urdf/meshes/four_wheel_diff_dl_robot_meshes/controller_link.STL" />
      </geometry>
    </collision>
  </link>
  <joint
    name="controller_joint"
    type="fixed">
    <origin
      xyz="0.101379911991688 0.0620176418028517 0.00150000000000053"
      rpy="0 0 0" />
    <parent
      link="base_link" />
    <child
      link="controller_link" />
    <axis
      xyz="0 0 0" />
  </joint>
</robot>
