<?xml version="1.0" encoding="utf-8"?>
<!-- This URDF was automatically created by SolidWorks to URDF Exporter! Originally created by Stephen Brawner (brawner@gmail.com) 
     Commit Version: 1.6.0-4-g7f85cfe  Build Version: 1.6.7995.38578
     For more information, please see http://wiki.ros.org/sw_urdf_exporter -->
<robot
  name="four_wheel_diff_bs_robot">
  <link
    name="base_link">
    <inertial>
      <origin
        xyz="0.0462629834005749 -0.00405781340954342 0.0282831399530564"
        rpy="0 0 0" />
      <mass
        value="4.71064836355498" />
      <inertia
        ixx="0.0538791577821187"
        ixy="6.45705427166123E-05"
        ixz="-1.84301924068733E-05"
        iyy="0.0466094447407305"
        iyz="-2.87984082042781E-06"
        izz="0.0970512808011448" />
    </inertial>
    <visual>
      <origin
        xyz="0 0 0"
        rpy="0 0 0" />
      <geometry>
        <mesh
          filename="package://wheeltec_robot_urdf/meshes/four_wheel_diff_bs_robot_meshes/base_link.STL" />
      </geometry>
      <material
        name="">
        <color
          rgba="0.741176470588235 0.901960784313726 0.956862745098039 1" />
      </material>
    </visual>
    <collision>
      <origin
        xyz="0 0 0"
        rpy="0 0 0" />
      <geometry>
        <mesh
          filename="package://wheeltec_robot_urdf/meshes/four_wheel_diff_bs_robot_meshes/base_link.STL" />
      </geometry>
    </collision>
  </link>
  <link
    name="lf_wheel_link">
    <inertial>
      <origin
        xyz="3.61401096549141E-09 -0.00244390627203289 -1.01287948499479E-05"
        rpy="0 0 0" />
      <mass
        value="0.566219483453613" />
      <inertia
        ixx="0.00187017809667248"
        ixy="2.73384573500602E-11"
        ixz="-1.09251537114813E-11"
        iyy="0.00344355982029273"
        iyz="-6.16603281053067E-08"
        izz="0.00187037499128627" />
    </inertial>
    <visual>
      <origin
        xyz="0 0 0"
        rpy="0 0 0" />
      <geometry>
        <mesh
          filename="package://wheeltec_robot_urdf/meshes/four_wheel_diff_bs_robot_meshes/lf_wheel_link.STL" />
      </geometry>
      <material
        name="">
        <color
          rgba="0.376470588235294 0.376470588235294 0.376470588235294 1" />
      </material>
    </visual>
    <collision>
      <origin
        xyz="0 0 0"
        rpy="0 0 0" />
      <geometry>
        <mesh
          filename="package://wheeltec_robot_urdf/meshes/four_wheel_diff_bs_robot_meshes/lf_wheel_link.STL" />
      </geometry>
    </collision>
  </link>
  <joint
    name="lf_wheel_joint"
    type="continuous">
    <origin
      xyz="0.185693160645845 0.299417641802976 -0.037499999999996"
      rpy="0 0 0" />
    <parent
      link="base_link" />
    <child
      link="lf_wheel_link" />
    <axis
      xyz="0 1 0" />
  </joint>
  <link
    name="lb_wheel_link">
    <inertial>
      <origin
        xyz="1.27184909236022E-05 -0.00140944981536266 -1.83669455708357E-06"
        rpy="0 0 0" />
      <mass
        value="0.371771326831592" />
      <inertia
        ixx="0.00118734293761529"
        ixy="5.34104888593155E-08"
        ixz="1.22699421706837E-08"
        iyy="0.00229211164387072"
        iyz="3.93539110083801E-09"
        izz="0.00118730966810385" />
    </inertial>
    <visual>
      <origin
        xyz="0 0 0"
        rpy="0 0 0" />
      <geometry>
        <mesh
          filename="package://wheeltec_robot_urdf/meshes/four_wheel_diff_bs_robot_meshes/lb_wheel_link.STL" />
      </geometry>
      <material
        name="">
        <color
          rgba="1 1 1 1" />
      </material>
    </visual>
    <collision>
      <origin
        xyz="0 0 0"
        rpy="0 0 0" />
      <geometry>
        <mesh
          filename="package://wheeltec_robot_urdf/meshes/four_wheel_diff_bs_robot_meshes/lb_wheel_link.STL" />
      </geometry>
    </collision>
  </link>
  <joint
    name="lb_wheel_joint"
    type="continuous">
    <origin
      xyz="-0.168006839354155 0.289417641802975 -0.037499999999996"
      rpy="0 0 0" />
    <parent
      link="base_link" />
    <child
      link="lb_wheel_link" />
    <axis
      xyz="0 -1 0" />
  </joint>
  <link
    name="rb_wheel_link">
    <inertial>
      <origin
        xyz="-1.27184909264333E-05 0.00140944981536306 -1.83669456016444E-06"
        rpy="0 0 0" />
      <mass
        value="0.371771326831597" />
      <inertia
        ixx="0.00118734293761531"
        ixy="5.34104888625947E-08"
        ixz="-1.22699421961148E-08"
        iyy="0.00229211164387076"
        iyz="-3.93539108664747E-09"
        izz="0.00118730966810387" />
    </inertial>
    <visual>
      <origin
        xyz="0 0 0"
        rpy="0 0 0" />
      <geometry>
        <mesh
          filename="package://wheeltec_robot_urdf/meshes/four_wheel_diff_bs_robot_meshes/rb_wheel_link.STL" />
      </geometry>
      <material
        name="">
        <color
          rgba="1 1 1 1" />
      </material>
    </visual>
    <collision>
      <origin
        xyz="0 0 0"
        rpy="0 0 0" />
      <geometry>
        <mesh
          filename="package://wheeltec_robot_urdf/meshes/four_wheel_diff_bs_robot_meshes/rb_wheel_link.STL" />
      </geometry>
    </collision>
  </link>
  <joint
    name="rb_wheel_joint"
    type="continuous">
    <origin
      xyz="-0.168006839354153 -0.288382358197025 -0.037499999999994"
      rpy="0 0 0" />
    <parent
      link="base_link" />
    <child
      link="rb_wheel_link" />
    <axis
      xyz="0 1 0" />
  </joint>
  <link
    name="rf_wheel_link">
    <inertial>
      <origin
        xyz="-3.6140115483585E-09 0.0024439062720325 -1.01287948487405E-05"
        rpy="0 0 0" />
      <mass
        value="0.566219483453626" />
      <inertia
        ixx="0.0018701780966725"
        ixy="2.73384789114296E-11"
        ixz="1.09251492780988E-11"
        iyy="0.00344355982029283"
        iyz="6.16603280955541E-08"
        izz="0.00187037499128633" />
    </inertial>
    <visual>
      <origin
        xyz="0 0 0"
        rpy="0 0 0" />
      <geometry>
        <mesh
          filename="package://wheeltec_robot_urdf/meshes/four_wheel_diff_bs_robot_meshes/rf_wheel_link.STL" />
      </geometry>
      <material
        name="">
        <color
          rgba="0.741176470588235 0.901960784313726 0.956862745098039 1" />
      </material>
    </visual>
    <collision>
      <origin
        xyz="0 0 0"
        rpy="0 0 0" />
      <geometry>
        <mesh
          filename="package://wheeltec_robot_urdf/meshes/four_wheel_diff_bs_robot_meshes/rf_wheel_link.STL" />
      </geometry>
    </collision>
  </link>
  <joint
    name="rf_wheel_joint"
    type="continuous">
    <origin
      xyz="0.185693160645847 -0.299382358197024 -0.037499999999994"
      rpy="0 0 0" />
    <parent
      link="base_link" />
    <child
      link="rf_wheel_link" />
    <axis
      xyz="0 -1 0" />
  </joint>
  <link
    name="camera_link">
    <inertial>
      <origin
        xyz="-1.49472340595092E-07 1.5737615574607E-07 -3.19615127974959E-07"
        rpy="0 0 0" />
      <mass
        value="0.055984252920277" />
      <inertia
        ixx="0.000130802200744622"
        ixy="-9.96617453034004E-07"
        ixz="1.62299342697034E-06"
        iyy="1.9123626272978E-05"
        iyz="-4.42334063842044E-08"
        izz="0.000131387473459422" />
    </inertial>
    <visual>
      <origin
        xyz="0 0 0"
        rpy="0 0 0" />
      <geometry>
        <mesh
          filename="package://wheeltec_robot_urdf/meshes/four_wheel_diff_bs_robot_meshes/camera_link.STL" />
      </geometry>
      <material
        name="">
        <color
          rgba="1 1 1 1" />
      </material>
    </visual>
    <collision>
      <origin
        xyz="0 0 0"
        rpy="0 0 0" />
      <geometry>
        <mesh
          filename="package://wheeltec_robot_urdf/meshes/four_wheel_diff_bs_robot_meshes/camera_link.STL" />
      </geometry>
    </collision>
  </link>
  <joint
    name="camera_joint"
    type="fixed">
    <origin
      xyz="0.298787160645846 0.000240641802977143 0.172196000000005"
      rpy="0 0 0" />
    <parent
      link="base_link" />
    <child
      link="camera_link" />
    <axis
      xyz="0 0 0" />
  </joint>
  <link
    name="laser_link">
    <inertial>
      <origin
        xyz="-0.00207956288634144 -9.87028646592947E-07 -0.0264472435671745"
        rpy="0 0 0" />
      <mass
        value="0.00426368606026277" />
      <inertia
        ixx="1.45373992961577E-06"
        ixy="2.48436940264113E-14"
        ixz="-8.86181044864516E-08"
        iyy="1.17647720289551E-06"
        iyz="-2.28919926237116E-15"
        izz="2.03836666874871E-06" />
    </inertial>
    <visual>
      <origin
        xyz="0 0 0"
        rpy="0 0 0" />
      <geometry>
        <mesh
          filename="package://wheeltec_robot_urdf/meshes/four_wheel_diff_bs_robot_meshes/laser.STL" />
      </geometry>
      <material
        name="">
        <color
          rgba="0.376470588235294 0.376470588235294 0.376470588235294 1" />
      </material>
    </visual>
    <collision>
      <origin
        xyz="0 0 0"
        rpy="0 0 0" />
      <geometry>
        <mesh
          filename="package://wheeltec_robot_urdf/meshes/four_wheel_diff_bs_robot_meshes/laser.STL" />
      </geometry>
    </collision>
  </link>
  <joint
    name="laser_joint"
    type="fixed">
    <origin
      xyz="0.246992160645846 1.66418029772242E-05 0.244656000000005"
      rpy="0 0 -3.14159265358979" />
    <parent
      link="base_link" />
    <child
      link="laser_link" />
    <axis
      xyz="0 0 0" />
  </joint>
  <link
    name="controller_link">
    <inertial>
      <origin
        xyz="-0.0497103400790872 0.0175133935293348 0.00856001460559358"
        rpy="0 0 0" />
      <mass
        value="0.00107921953110442" />
      <inertia
        ixx="1.16330109775188E-08"
        ixy="-3.9409266886985E-09"
        ixz="3.69212784612827E-10"
        iyy="2.26830020206351E-07"
        iyz="5.23015130069644E-10"
        izz="2.25657042461938E-07" />
    </inertial>
    <visual>
      <origin
        xyz="0 0 0"
        rpy="0 0 0" />
      <geometry>
        <mesh
          filename="package://wheeltec_robot_urdf/meshes/four_wheel_diff_bs_robot_meshes/controller_link.STL" />
      </geometry>
      <material
        name="">
        <color
          rgba="0.741176470588235 0.901960784313726 0.956862745098039 1" />
      </material>
    </visual>
    <collision>
      <origin
        xyz="0 0 0"
        rpy="0 0 0" />
      <geometry>
        <mesh
          filename="package://wheeltec_robot_urdf/meshes/four_wheel_diff_bs_robot_meshes/controller_link.STL" />
      </geometry>
    </collision>
  </link>
  <joint
    name="controller_joint"
    type="fixed">
    <origin
      xyz="0.101379911991688 0.0620176418028517 0.00150000000000056"
      rpy="0 0 0" />
    <parent
      link="base_link" />
    <child
      link="controller_link" />
    <axis
      xyz="0 0 0" />
  </joint>
</robot>
