<?xml version="1.0" encoding="utf-8"?>
<!-- This URDF was automatically created by SolidWorks to URDF Exporter! Originally created by Stephen Brawner (brawner@gmail.com) 
     Commit Version: 1.6.0-4-g7f85cfe  Build Version: 1.6.7995.38578
     For more information, please see http://wiki.ros.org/sw_urdf_exporter -->
<robot
  name="r3s_mec_robot">
  <link
    name="base_link">
    <inertial>
      <origin
        xyz="-0.00658271210809724 0.000569960640804681 0.0414948422314003"
        rpy="0 0 0" />
      <mass
        value="0.486844981490714" />
      <inertia
        ixx="0.000728879704405369"
        ixy="-1.95581978182495E-06"
        ixz="1.38866314723912E-05"
        iyy="0.00137349892998219"
        iyz="1.27363604508813E-06"
        izz="0.00198018890840461" />
    </inertial>
    <visual>
      <origin
        xyz="0 0 0"
        rpy="0 0 0" />
      <geometry>
        <mesh
          filename="package://wheeltec_robot_urdf/meshes/r3s_mec_robot_meshes/base_link.STL" />
      </geometry>
      <material
        name="">
        <color
          rgba="0.349019607843137 0.349019607843137 0.349019607843137 1" />
      </material>
    </visual>
    <collision>
      <origin
        xyz="0 0 0"
        rpy="0 0 0" />
      <geometry>
        <mesh
          filename="package://wheeltec_robot_urdf/meshes/r3s_mec_robot_meshes/base_link.STL" />
      </geometry>
    </collision>
  </link>
  <link
    name="lf_wheel_link">
    <inertial>
      <origin
        xyz="-7.70853984810582E-10 -0.00391716682736307 -1.4561503738908E-10"
        rpy="0 0 0" />
      <mass
        value="0.0575555911293518" />
      <inertia
        ixx="2.10755821421772E-05"
        ixy="-2.16920667058315E-13"
        ixz="-1.66749355467763E-13"
        iyy="3.40216676430615E-05"
        iyz="-3.16177321306463E-14"
        izz="2.10755819831363E-05" />
    </inertial>
    <visual>
      <origin
        xyz="0 0 0"
        rpy="0 0 0" />
      <geometry>
        <mesh
          filename="package://wheeltec_robot_urdf/meshes/r3s_mec_robot_meshes/lf_wheel_link.STL" />
      </geometry>
      <material
        name="">
        <color
          rgba="0.376470588235294 0.376470588235294 0.376470588235294 1" />
      </material>
    </visual>
    <collision>
      <origin
        xyz="0 0 0"
        rpy="0 0 0" />
      <geometry>
        <mesh
          filename="package://wheeltec_robot_urdf/meshes/r3s_mec_robot_meshes/lf_wheel_link.STL" />
      </geometry>
    </collision>
  </link>
  <joint
    name="lf_wheel_joint"
    type="continuous">
    <origin
      xyz="0.0759419119540792 0.0983014469516561 0.0167"
      rpy="0 0 0" />
    <parent
      link="base_link" />
    <child
      link="lf_wheel_link" />
    <axis
      xyz="0 -1 0" />
  </joint>
  <link
    name="lb_wheel_link">
    <inertial>
      <origin
        xyz="8.27298508865315E-09 -0.00391801534011008 2.33900100711504E-08"
        rpy="0 0 0" />
      <mass
        value="0.0575546594328681" />
      <inertia
        ixx="2.10751269181675E-05"
        ixy="-1.20264905096543E-12"
        ixz="-7.94357439958831E-12"
        iyy="3.40209427021929E-05"
        iyz="5.32083294576981E-12"
        izz="2.10751450994036E-05" />
    </inertial>
    <visual>
      <origin
        xyz="0 0 0"
        rpy="0 0 0" />
      <geometry>
        <mesh
          filename="package://wheeltec_robot_urdf/meshes/r3s_mec_robot_meshes/lb_wheel_link.STL" />
      </geometry>
      <material
        name="">
        <color
          rgba="0.376470588235294 0.376470588235294 0.376470588235294 1" />
      </material>
    </visual>
    <collision>
      <origin
        xyz="0 0 0"
        rpy="0 0 0" />
      <geometry>
        <mesh
          filename="package://wheeltec_robot_urdf/meshes/r3s_mec_robot_meshes/lb_wheel_link.STL" />
      </geometry>
    </collision>
  </link>
  <joint
    name="lb_wheel_joint"
    type="continuous">
    <origin
      xyz="-0.0816580880459208 0.0983054469516561 0.0167"
      rpy="0 0 0" />
    <parent
      link="base_link" />
    <child
      link="lb_wheel_link" />
    <axis
      xyz="0 1 0" />
  </joint>
  <link
    name="rb_wheel_link">
    <inertial>
      <origin
        xyz="7.24978507782303E-10 0.00391716682736308 2.99709913137436E-10"
        rpy="0 0 0" />
      <mass
        value="0.0575555911293519" />
      <inertia
        ixx="2.10755819418964E-05"
        ixy="-1.98892413173438E-13"
        ixz="1.39806284049536E-13"
        iyy="3.40216676430614E-05"
        iyz="-9.21741113361527E-14"
        izz="2.10755821834171E-05" />
    </inertial>
    <visual>
      <origin
        xyz="0 0 0"
        rpy="0 0 0" />
      <geometry>
        <mesh
          filename="package://wheeltec_robot_urdf/meshes/r3s_mec_robot_meshes/rb_wheel_link.STL" />
      </geometry>
      <material
        name="">
        <color
          rgba="0.376470588235294 0.376470588235294 0.376470588235294 1" />
      </material>
    </visual>
    <collision>
      <origin
        xyz="0 0 0"
        rpy="0 0 0" />
      <geometry>
        <mesh
          filename="package://wheeltec_robot_urdf/meshes/r3s_mec_robot_meshes/rb_wheel_link.STL" />
      </geometry>
    </collision>
  </link>
  <joint
    name="rb_wheel_joint"
    type="continuous">
    <origin
      xyz="-0.0816580880459208 -0.0982745530483439 0.0167"
      rpy="0 0 0" />
    <parent
      link="base_link" />
    <child
      link="rb_wheel_link" />
    <axis
      xyz="0 1 0" />
  </joint>
  <link
    name="rf_wheel_link">
    <inertial>
      <origin
        xyz="-2.03118767638788E-08 0.00391801536357496 1.47898364041832E-08"
        rpy="0 0 0" />
      <mass
        value="0.0575546595056713" />
      <inertia
        ixx="2.10751249334216E-05"
        ixy="1.27911217452893E-12"
        ixz="-5.19497190132298E-12"
        iyy="3.40209423643432E-05"
        iyz="-5.39837364479759E-12"
        izz="2.1075146790306E-05" />
    </inertial>
    <visual>
      <origin
        xyz="0 0 0"
        rpy="0 0 0" />
      <geometry>
        <mesh
          filename="package://wheeltec_robot_urdf/meshes/r3s_mec_robot_meshes/rf_wheel_link.STL" />
      </geometry>
      <material
        name="">
        <color
          rgba="0.376470588235294 0.376470588235294 0.376470588235294 1" />
      </material>
    </visual>
    <collision>
      <origin
        xyz="0 0 0"
        rpy="0 0 0" />
      <geometry>
        <mesh
          filename="package://wheeltec_robot_urdf/meshes/r3s_mec_robot_meshes/rf_wheel_link.STL" />
      </geometry>
    </collision>
  </link>
  <joint
    name="rf_wheel_joint"
    type="continuous">
    <origin
      xyz="0.0759419119540792 -0.0982785530483439 0.0167"
      rpy="0 0 0" />
    <parent
      link="base_link" />
    <child
      link="rf_wheel_link" />
    <axis
      xyz="0 -1 0" />
  </joint>
  <link
    name="camera_link">
    <inertial>
      <origin
        xyz="-4.45004837215657E-08 -3.25846249904076E-07 -0.0139995077279642"
        rpy="0 0 0" />
      <mass
        value="0.0285970249307156" />
      <inertia
        ixx="2.49063659552752E-05"
        ixy="1.41446622396731E-09"
        ixz="-3.44746104888009E-07"
        iyy="8.10339394659798E-06"
        iyz="8.7411817335606E-09"
        izz="1.91138588188251E-05" />
    </inertial>
    <visual>
      <origin
        xyz="0 0 0"
        rpy="0 0 0" />
      <geometry>
        <mesh
          filename="package://wheeltec_robot_urdf/meshes/r3s_mec_robot_meshes/camera_link.STL" />
      </geometry>
      <material
        name="">
        <color
          rgba="1 1 1 1" />
      </material>
    </visual>
    <collision>
      <origin
        xyz="0 0 0"
        rpy="0 0 0" />
      <geometry>
        <mesh
          filename="package://wheeltec_robot_urdf/meshes/r3s_mec_robot_meshes/camera_link.STL" />
      </geometry>
    </collision>
  </link>
  <joint
    name="camera_joint"
    type="fixed">
    <origin
      xyz="0.00160091195407919 -0.00010055304834393 0.152137"
      rpy="0 0 0" />
    <parent
      link="base_link" />
    <child
      link="camera_link" />
    <axis
      xyz="0 0 0" />
  </joint>
  <link
    name="laser_link">
    <inertial>
      <origin
        xyz="0.000735465990626988 2.79287293896135E-07 -0.00549379656778799"
        rpy="0 0 0" />
      <mass
        value="0.000111381912632097" />
      <inertia
        ixx="8.09810255937586E-10"
        ixy="2.48436925682356E-14"
        ixz="-2.38955091202816E-14"
        iyy="8.09668177063905E-10"
        iyz="-2.28917457095815E-15"
        izz="1.17057115150887E-10" />
    </inertial>
    <visual>
      <origin
        xyz="0 0 0"
        rpy="0 0 0" />
      <geometry>
        <mesh
          filename="package://wheeltec_robot_urdf/meshes/r3s_mec_robot_meshes/laser.STL" />
      </geometry>
      <material
        name="">
        <color
          rgba="0.376470588235294 0.376470588235294 0.376470588235294 1" />
      </material>
    </visual>
    <collision>
      <origin
        xyz="0 0 0"
        rpy="0 0 0" />
      <geometry>
        <mesh
          filename="package://wheeltec_robot_urdf/meshes/r3s_mec_robot_meshes/laser.STL" />
      </geometry>
    </collision>
  </link>
  <joint
    name="laser_joint"
    type="fixed">
    <origin
      xyz="0.0834767944381037 1.32296970929568E-05 0.09655"
      rpy="0 0 -3.14159265358979" />
    <parent
      link="base_link" />
    <child
      link="laser_link" />
    <axis
      xyz="0 0 0" />
  </joint>
  <link
    name="controller_link">
    <inertial>
      <origin
        xyz="-0.0254318317483443 0.0178325189887231 0.0120915107345509"
        rpy="0 0 0" />
      <mass
        value="0.0371650711916722" />
      <inertia
        ixx="2.75273128086897E-05"
        ixy="-4.90416948087793E-07"
        ixz="-8.95619686706703E-08"
        iyy="1.08853888864562E-05"
        iyz="3.79055088929114E-07"
        izz="3.7257082402319E-05" />
    </inertial>
    <visual>
      <origin
        xyz="0 0 0"
        rpy="0 0 0" />
      <geometry>
        <mesh
          filename="package://wheeltec_robot_urdf/meshes/r3s_mec_robot_meshes/controller_link.STL" />
      </geometry>
      <material
        name="">
        <color
          rgba="1 1 1 1" />
      </material>
    </visual>
    <collision>
      <origin
        xyz="0 0 0"
        rpy="0 0 0" />
      <geometry>
        <mesh
          filename="package://wheeltec_robot_urdf/meshes/r3s_mec_robot_meshes/controller_link.STL" />
      </geometry>
    </collision>
  </link>
  <joint
    name="controller_joint"
    type="fixed">
    <origin
      xyz="-0.0539080491826598 -0.011432266551253 0.1135"
      rpy="0 0 0" />
    <parent
      link="base_link" />
    <child
      link="controller_link" />
    <axis
      xyz="0 0 0" />
  </joint>
</robot>
