<?xml version="1.0" encoding="utf-8"?>
<!-- This URDF was automatically created by SolidWorks to URDF Exporter! Originally created by Stephen Brawner (brawner@gmail.com) 
     Commit Version: 1.6.0-4-g7f85cfe  Build Version: 1.6.7995.38578
     For more information, please see http://wiki.ros.org/sw_urdf_exporter -->
<robot
  name="senior_4wd_dl_robot">
  <link
    name="base_link">
    <inertial>
      <origin
        xyz="0.0039692875836891 -0.0169684540029386 0.042340176559083"
        rpy="0 0 0" />
      <mass
        value="3.61810836580839" />
      <inertia
        ixx="0.0123396483090898"
        ixy="-3.75420365719103E-05"
        ixz="1.71277627741974E-06"
        iyy="0.019138606943035"
        iyz="-4.72702121116256E-07"
        izz="0.0300647615679597" />
    </inertial>
    <visual>
      <origin
        xyz="0 0 0"
        rpy="0 0 0" />
      <geometry>
        <mesh
          filename="package://wheeltec_robot_urdf/meshes/senior_4wd_dl_robot_meshes/base_link.STL" />
      </geometry>
      <material
        name="">
        <color
          rgba="0.741176470588235 0.901960784313726 0.956862745098039 1" />
      </material>
    </visual>
    <collision>
      <origin
        xyz="0 0 0"
        rpy="0 0 0" />
      <geometry>
        <mesh
          filename="package://wheeltec_robot_urdf/meshes/senior_4wd_dl_robot_meshes/base_link.STL" />
      </geometry>
    </collision>
  </link>
  <link
    name="lf_wheel_link">
    <inertial>
      <origin
        xyz="2.75911313407651E-07 -3.91891407047762E-07 1.95859976084845E-07"
        rpy="0 0 0" />
      <mass
        value="0.700030715838823" />
      <inertia
        ixx="0.00126075310735644"
        ixy="4.1842907931992E-08"
        ixz="1.75903085626805E-08"
        iyy="0.00230176504241376"
        iyz="3.53598250582258E-08"
        izz="0.001260767507515" />
    </inertial>
    <visual>
      <origin
        xyz="0 0 0"
        rpy="0 0 0" />
      <geometry>
        <mesh
          filename="package://wheeltec_robot_urdf/meshes/senior_4wd_dl_robot_meshes/lf_wheel_link.STL" />
      </geometry>
      <material
        name="">
        <color
          rgba="1 1 1 1" />
      </material>
    </visual>
    <collision>
      <origin
        xyz="0 0 0"
        rpy="0 0 0" />
      <geometry>
        <mesh
          filename="package://wheeltec_robot_urdf/meshes/senior_4wd_dl_robot_meshes/lf_wheel_link.STL" />
      </geometry>
    </collision>
  </link>
  <joint
    name="lf_wheel_joint"
    type="continuous">
    <origin
      xyz="0.213999160724458 0.242590433959339 0.016470999999997"
      rpy="0 0 0" />
    <parent
      link="base_link" />
    <child
      link="lf_wheel_link" />
    <axis
      xyz="0 -0.999999999999996 0" />
  </joint>
  <link
    name="lb_wheel_link">
    <inertial>
      <origin
        xyz="2.75911313435406E-07 -3.91891407020006E-07 1.95859976070967E-07"
        rpy="0 0 0" />
      <mass
        value="0.700030715838822" />
      <inertia
        ixx="0.00126075310735644"
        ixy="4.18429079320475E-08"
        ixz="1.75903085626591E-08"
        iyy="0.00230176504241376"
        iyz="3.53598250582156E-08"
        izz="0.001260767507515" />
    </inertial>
    <visual>
      <origin
        xyz="0 0 0"
        rpy="0 0 0" />
      <geometry>
        <mesh
          filename="package://wheeltec_robot_urdf/meshes/senior_4wd_dl_robot_meshes/lb_wheel_link.STL" />
      </geometry>
      <material
        name="">
        <color
          rgba="1 1 1 1" />
      </material>
    </visual>
    <collision>
      <origin
        xyz="0 0 0"
        rpy="0 0 0" />
      <geometry>
        <mesh
          filename="package://wheeltec_robot_urdf/meshes/senior_4wd_dl_robot_meshes/lb_wheel_link.STL" />
      </geometry>
    </collision>
  </link>
  <joint
    name="lb_wheel_joint"
    type="continuous">
    <origin
      xyz="-0.214000839275542 0.24259043395934 0.016470999999997"
      rpy="0 0 0" />
    <parent
      link="base_link" />
    <child
      link="lb_wheel_link" />
    <axis
      xyz="0 -0.999999999999996 0" />
  </joint>
  <link
    name="rb_wheel_link">
    <inertial>
      <origin
        xyz="-2.76184052544481E-07 3.91972408864127E-07 1.95859973087242E-07"
        rpy="0 0 0" />
      <mass
        value="0.700030715838823" />
      <inertia
        ixx="0.00126075310735685"
        ixy="4.18480167241891E-08"
        ixz="-1.75903087363996E-08"
        iyy="0.00230176504241335"
        iyz="-3.53598249717642E-08"
        izz="0.001260767507515" />
    </inertial>
    <visual>
      <origin
        xyz="0 0 0"
        rpy="0 0 0" />
      <geometry>
        <mesh
          filename="package://wheeltec_robot_urdf/meshes/senior_4wd_dl_robot_meshes/rb_wheel_link.STL" />
      </geometry>
      <material
        name="">
        <color
          rgba="1 1 1 1" />
      </material>
    </visual>
    <collision>
      <origin
        xyz="0 0 0"
        rpy="0 0 0" />
      <geometry>
        <mesh
          filename="package://wheeltec_robot_urdf/meshes/senior_4wd_dl_robot_meshes/rb_wheel_link.STL" />
      </geometry>
    </collision>
  </link>
  <joint
    name="rb_wheel_joint"
    type="continuous">
    <origin
      xyz="-0.214012839275544 -0.23856356604066 0.016470999999997"
      rpy="0 0 0" />
    <parent
      link="base_link" />
    <child
      link="rb_wheel_link" />
    <axis
      xyz="0 0.999999999999996 0" />
  </joint>
  <link
    name="rf_wheel_link">
    <inertial>
      <origin
        xyz="-2.76184052461215E-07 3.91972408919639E-07 1.9585997310112E-07"
        rpy="0 0 0" />
      <mass
        value="0.700030715838823" />
      <inertia
        ixx="0.00126075310735685"
        ixy="4.18480167242432E-08"
        ixz="-1.75903087364055E-08"
        iyy="0.00230176504241335"
        iyz="-3.5359824971763E-08"
        izz="0.001260767507515" />
    </inertial>
    <visual>
      <origin
        xyz="0 0 0"
        rpy="0 0 0" />
      <geometry>
        <mesh
          filename="package://wheeltec_robot_urdf/meshes/senior_4wd_dl_robot_meshes/rf_wheel_link.STL" />
      </geometry>
      <material
        name="">
        <color
          rgba="1 1 1 1" />
      </material>
    </visual>
    <collision>
      <origin
        xyz="0 0 0"
        rpy="0 0 0" />
      <geometry>
        <mesh
          filename="package://wheeltec_robot_urdf/meshes/senior_4wd_dl_robot_meshes/rf_wheel_link.STL" />
      </geometry>
    </collision>
  </link>
  <joint
    name="rf_wheel_joint"
    type="continuous">
    <origin
      xyz="0.213987160724456 -0.238563566040661 0.016470999999997"
      rpy="0 0 0" />
    <parent
      link="base_link" />
    <child
      link="rf_wheel_link" />
    <axis
      xyz="0 0.999999999999996 0" />
  </joint>
  <link
    name="camera_link">
    <inertial>
      <origin
        xyz="3.44868297197376E-07 -3.53598340584031E-07 1.07617269679006E-07"
        rpy="0 0 0" />
      <mass
        value="0.0559842512667172" />
      <inertia
        ixx="0.000130810959355656"
        ixy="1.20255121404777E-07"
        ixz="1.62335437373898E-06"
        iyy="1.91148635028013E-05"
        iyz="-2.80016695785784E-08"
        izz="0.000131387469540189" />
    </inertial>
    <visual>
      <origin
        xyz="0 0 0"
        rpy="0 0 0" />
      <geometry>
        <mesh
          filename="package://wheeltec_robot_urdf/meshes/senior_4wd_dl_robot_meshes/camera_link.STL" />
      </geometry>
      <material
        name="">
        <color
          rgba="1 1 1 1" />
      </material>
    </visual>
    <collision>
      <origin
        xyz="0 0 0"
        rpy="0 0 0" />
      <geometry>
        <mesh
          filename="package://wheeltec_robot_urdf/meshes/senior_4wd_dl_robot_meshes/camera_link.STL" />
      </geometry>
    </collision>
  </link>
  <joint
    name="camera_joint"
    type="fixed">
    <origin
      xyz="0.231597160724457 0.00224143395933855 0.128203999999997"
      rpy="0 0 0" />
    <parent
      link="base_link" />
    <child
      link="camera_link" />
    <axis
      xyz="0 0 0" />
  </joint>
  <link
    name="laser_link">
    <inertial>
      <origin
        xyz="0.00196458631092417 -3.57895369235698E-06 -0.000201831632183791"
        rpy="0 0 0" />
      <mass
        value="0.0477519163700356" />
      <inertia
        ixx="3.38461999734689E-05"
        ixy="-2.19897049050811E-09"
        ixz="1.07118468692931E-06"
        iyy="3.9415041585171E-05"
        iyz="6.83978477324344E-10"
        izz="5.60787042097609E-05" />
    </inertial>
    <visual>
      <origin
        xyz="0 0 0"
        rpy="0 0 0" />
      <geometry>
        <mesh
          filename="package://wheeltec_robot_urdf/meshes/senior_4wd_dl_robot_meshes/laser.STL" />
      </geometry>
      <material
        name="">
        <color
          rgba="0.376470588235294 0.376470588235294 0.376470588235294 1" />
      </material>
    </visual>
    <collision>
      <origin
        xyz="0 0 0"
        rpy="0 0 0" />
      <geometry>
        <mesh
          filename="package://wheeltec_robot_urdf/meshes/senior_4wd_dl_robot_meshes/laser.STL" />
      </geometry>
    </collision>
  </link>
  <joint
    name="laser_joint"
    type="fixed">
    <origin
      xyz="0.156992810769455 0.00201378391434084 0.146524183741428"
      rpy="0 0 3.14159265358979" />
    <parent
      link="base_link" />
    <child
      link="laser_link" />
    <axis
      xyz="0 0 0" />
  </joint>
  <link
    name="controller_link">
    <inertial>
      <origin
        xyz="-0.049710340079087 0.0175133935293354 0.00856001460559375"
        rpy="0 0 0" />
      <mass
        value="0.00107921953110443" />
      <inertia
        ixx="1.16330109775188E-08"
        ixy="-3.94092668869415E-09"
        ixz="3.69212784612903E-10"
        iyy="2.26830020206353E-07"
        iyz="5.23015130069675E-10"
        izz="2.2565704246194E-07" />
    </inertial>
    <visual>
      <origin
        xyz="0 0 0"
        rpy="0 0 0" />
      <geometry>
        <mesh
          filename="package://wheeltec_robot_urdf/meshes/senior_4wd_dl_robot_meshes/controller_link.STL" />
      </geometry>
      <material
        name="">
        <color
          rgba="0.741176470588235 0.901960784313726 0.956862745098039 1" />
      </material>
    </visual>
    <collision>
      <origin
        xyz="0 0 0"
        rpy="0 0 0" />
      <geometry>
        <mesh
          filename="package://wheeltec_robot_urdf/meshes/senior_4wd_dl_robot_meshes/controller_link.STL" />
      </geometry>
    </collision>
  </link>
  <joint
    name="controller_joint"
    type="fixed">
    <origin
      xyz="0.101379911991689 0.0620176418028498 0.00150000000000076"
      rpy="0 0 0" />
    <parent
      link="base_link" />
    <child
      link="controller_link" />
    <axis
      xyz="0 0 0" />
  </joint>
</robot>
