<?xml version="1.0" encoding="utf-8"?>
<!-- This URDF was automatically created by SolidWorks to URDF Exporter! Originally created by Stephen Brawner (brawner@gmail.com) 
     Commit Version: 1.6.0-4-g7f85cfe  Build Version: 1.6.7995.38578
     For more information, please see http://wiki.ros.org/sw_urdf_exporter -->
<robot
  name="senior_mec_dl_robot">
  <link
    name="base_link">
    <inertial>
      <origin
        xyz="0.00395812997139428 -0.0181699700367143 0.0426976808291864"
        rpy="0 0 0" />
      <mass
        value="3.63363059228835" />
      <inertia
        ixx="0.0123476894434173"
        ixy="-3.75380777513439E-05"
        ixz="3.2955850810326E-06"
        iyy="0.0191530909543642"
        iyz="-4.72702736402811E-07"
        izz="0.0300856570898858" />
    </inertial>
    <visual>
      <origin
        xyz="0 0 0"
        rpy="0 0 0" />
      <geometry>
        <mesh
          filename="package://wheeltec_robot_urdf/meshes/senior_mec_dl_robot_meshes/base_link.STL" />
      </geometry>
      <material
        name="">
        <color
          rgba="0.741176470588235 0.901960784313726 0.956862745098039 1" />
      </material>
    </visual>
    <collision>
      <origin
        xyz="0 0 0"
        rpy="0 0 0" />
      <geometry>
        <mesh
          filename="package://wheeltec_robot_urdf/meshes/senior_mec_dl_robot_meshes/base_link.STL" />
      </geometry>
    </collision>
  </link>
  <link
    name="lf_wheel_link">
    <inertial>
      <origin
        xyz="1.59463379857394E-05 -0.00251989341236478 4.50644259958333E-06"
        rpy="0 0 0" />
      <mass
        value="0.242981515052131" />
      <inertia
        ixx="0.000457072694528196"
        ixy="-1.9250151988867E-07"
        ixz="1.81223948807993E-08"
        iyy="0.000868054982970888"
        iyz="1.62139611461968E-08"
        izz="0.000456492835033346" />
    </inertial>
    <visual>
      <origin
        xyz="0 0 0"
        rpy="0 0 0" />
      <geometry>
        <mesh
          filename="package://wheeltec_robot_urdf/meshes/senior_mec_dl_robot_meshes/lf_wheel_link.STL" />
      </geometry>
      <material
        name="">
        <color
          rgba="1 1 1 1" />
      </material>
    </visual>
    <collision>
      <origin
        xyz="0 0 0"
        rpy="0 0 0" />
      <geometry>
        <mesh
          filename="package://wheeltec_robot_urdf/meshes/senior_mec_dl_robot_meshes/lf_wheel_link.STL" />
      </geometry>
    </collision>
  </link>
  <joint
    name="lf_wheel_joint"
    type="continuous">
    <origin
      xyz="0.213993160645858 0.240475641802969 0.016474000000001"
      rpy="0 0 0" />
    <parent
      link="base_link" />
    <child
      link="lf_wheel_link" />
    <axis
      xyz="0 -0.999999999999996 0" />
  </joint>
  <link
    name="lb_wheel_link">
    <inertial>
      <origin
        xyz="1.59463380910441E-05 -0.00251989341229217 4.50644260036048E-06"
        rpy="0 0 0" />
      <mass
        value="0.242981515052133" />
      <inertia
        ixx="0.000457072694528221"
        ixy="-1.92501519890702E-07"
        ixz="1.81223938957395E-08"
        iyy="0.000868054982970891"
        iyz="1.62139604712804E-08"
        izz="0.000456492835033342" />
    </inertial>
    <visual>
      <origin
        xyz="0 0 0"
        rpy="0 0 0" />
      <geometry>
        <mesh
          filename="package://wheeltec_robot_urdf/meshes/senior_mec_dl_robot_meshes/lb_wheel_link.STL" />
      </geometry>
      <material
        name="">
        <color
          rgba="1 1 1 1" />
      </material>
    </visual>
    <collision>
      <origin
        xyz="0 0 0"
        rpy="0 0 0" />
      <geometry>
        <mesh
          filename="package://wheeltec_robot_urdf/meshes/senior_mec_dl_robot_meshes/lb_wheel_link.STL" />
      </geometry>
    </collision>
  </link>
  <joint
    name="lb_wheel_joint"
    type="continuous">
    <origin
      xyz="-0.214006839354142 0.24047564180297 0.016474000000001"
      rpy="0 0 0" />
    <parent
      link="base_link" />
    <child
      link="lb_wheel_link" />
    <axis
      xyz="0 -0.999999999999996 0" />
  </joint>
  <link
    name="rb_wheel_link">
    <inertial>
      <origin
        xyz="-1.59465977699336E-05 0.00251989349341034 4.50644259479549E-06"
        rpy="0 0 0" />
      <mass
        value="0.242981515052113" />
      <inertia
        ixx="0.000457072694526328"
        ixy="-1.92499502994276E-07"
        ixz="-1.81223950058615E-08"
        iyy="0.000868054982972683"
        iyz="-1.6213961026137E-08"
        izz="0.000456492835033308" />
    </inertial>
    <visual>
      <origin
        xyz="0 0 0"
        rpy="0 0 0" />
      <geometry>
        <mesh
          filename="package://wheeltec_robot_urdf/meshes/senior_mec_dl_robot_meshes/rb_wheel_link.STL" />
      </geometry>
      <material
        name="">
        <color
          rgba="1 1 1 1" />
      </material>
    </visual>
    <collision>
      <origin
        xyz="0 0 0"
        rpy="0 0 0" />
      <geometry>
        <mesh
          filename="package://wheeltec_robot_urdf/meshes/senior_mec_dl_robot_meshes/rb_wheel_link.STL" />
      </geometry>
    </collision>
  </link>
  <joint
    name="rb_wheel_joint"
    type="continuous">
    <origin
      xyz="-0.214006839354144 -0.24044035819703 0.016474000000001"
      rpy="0 0 0" />
    <parent
      link="base_link" />
    <child
      link="rb_wheel_link" />
    <axis
      xyz="0 0.999999999999996 0" />
  </joint>
  <link
    name="rf_wheel_link">
    <inertial>
      <origin
        xyz="-1.59465979211737E-05 0.00251989349332665 4.50644254888777E-06"
        rpy="0 0 0" />
      <mass
        value="0.242981515051806" />
      <inertia
        ixx="0.000457072694525809"
        ixy="-1.92499502845376E-07"
        ixz="-1.81223936037035E-08"
        iyy="0.000868054982972009"
        iyz="-1.62139602190554E-08"
        izz="0.000456492835032971" />
    </inertial>
    <visual>
      <origin
        xyz="0 0 0"
        rpy="0 0 0" />
      <geometry>
        <mesh
          filename="package://wheeltec_robot_urdf/meshes/senior_mec_dl_robot_meshes/rf_wheel_link.STL" />
      </geometry>
      <material
        name="">
        <color
          rgba="1 1 1 1" />
      </material>
    </visual>
    <collision>
      <origin
        xyz="0 0 0"
        rpy="0 0 0" />
      <geometry>
        <mesh
          filename="package://wheeltec_robot_urdf/meshes/senior_mec_dl_robot_meshes/rf_wheel_link.STL" />
      </geometry>
    </collision>
  </link>
  <joint
    name="rf_wheel_joint"
    type="continuous">
    <origin
      xyz="0.213993160645856 -0.240440358197031 0.016474000000001"
      rpy="0 0 0" />
    <parent
      link="base_link" />
    <child
      link="rf_wheel_link" />
    <axis
      xyz="0 0.999999999999996 0" />
  </joint>
  <link
    name="camera_link">
    <inertial>
      <origin
        xyz="3.44868297197376E-07 -3.53598340572376E-07 1.07617269679006E-07"
        rpy="0 0 0" />
      <mass
        value="0.0559842512667171" />
      <inertia
        ixx="0.000130810959355657"
        ixy="1.20255121404776E-07"
        ixz="1.62335437373898E-06"
        iyy="1.91148635028014E-05"
        iyz="-2.800166957858E-08"
        izz="0.000131387469540189" />
    </inertial>
    <visual>
      <origin
        xyz="0 0 0"
        rpy="0 0 0" />
      <geometry>
        <mesh
          filename="package://wheeltec_robot_urdf/meshes/senior_mec_dl_robot_meshes/camera_link.STL" />
      </geometry>
      <material
        name="">
        <color
          rgba="1 1 1 1" />
      </material>
    </visual>
    <collision>
      <origin
        xyz="0 0 0"
        rpy="0 0 0" />
      <geometry>
        <mesh
          filename="package://wheeltec_robot_urdf/meshes/senior_mec_dl_robot_meshes/camera_link.STL" />
      </geometry>
    </collision>
  </link>
  <joint
    name="camera_joint"
    type="fixed">
    <origin
      xyz="0.231597160645857 0.000245641802968558 0.128204000000001"
      rpy="0 0 0" />
    <parent
      link="base_link" />
    <child
      link="camera_link" />
    <axis
      xyz="0 0 0" />
  </joint>
  <link
    name="laser_link">
    <inertial>
      <origin
        xyz="0.00196458631092417 -3.57895369235579E-06 -0.000201831632183805"
        rpy="0 0 0" />
      <mass
        value="0.0477519163700356" />
      <inertia
        ixx="3.38461999734689E-05"
        ixy="-2.19897049050557E-09"
        ixz="1.07118468692932E-06"
        iyy="3.9415041585171E-05"
        iyz="6.83978477325031E-10"
        izz="5.60787042097609E-05" />
    </inertial>
    <visual>
      <origin
        xyz="0 0 0"
        rpy="0 0 0" />
      <geometry>
        <mesh
          filename="package://wheeltec_robot_urdf/meshes/senior_mec_dl_robot_meshes/laser.STL" />
      </geometry>
      <material
        name="">
        <color
          rgba="0.376470588235294 0.376470588235294 0.376470588235294 1" />
      </material>
    </visual>
    <collision>
      <origin
        xyz="0 0 0"
        rpy="0 0 0" />
      <geometry>
        <mesh
          filename="package://wheeltec_robot_urdf/meshes/senior_mec_dl_robot_meshes/laser.STL" />
      </geometry>
    </collision>
  </link>
  <joint
    name="laser_joint"
    type="fixed">
    <origin
      xyz="0.156992810690855 1.79917579708449E-05 0.146524183741432"
      rpy="0 0 3.14159265358979" />
    <parent
      link="base_link" />
    <child
      link="laser_link" />
    <axis
      xyz="0 0 0" />
  </joint>
  <link
    name="controller_link">
    <inertial>
      <origin
        xyz="-0.0497103400547847 0.0175133932690561 0.00856001464881978"
        rpy="0 0 0" />
      <mass
        value="0.00107921954114689" />
      <inertia
        ixx="1.16330109995671E-08"
        ixy="-3.94092662514708E-09"
        ixz="3.69212982720616E-10"
        iyy="2.2683002186192E-07"
        iyz="5.23015112085359E-10"
        izz="2.25657044103421E-07" />
    </inertial>
    <visual>
      <origin
        xyz="0 0 0"
        rpy="0 0 0" />
      <geometry>
        <mesh
          filename="package://wheeltec_robot_urdf/meshes/senior_mec_dl_robot_meshes/controller_link.STL" />
      </geometry>
      <material
        name="">
        <color
          rgba="0.741176470588235 0.901960784313726 0.956862745098039 1" />
      </material>
    </visual>
    <collision>
      <origin
        xyz="0 0 0"
        rpy="0 0 0" />
      <geometry>
        <mesh
          filename="package://wheeltec_robot_urdf/meshes/senior_mec_dl_robot_meshes/controller_link.STL" />
      </geometry>
    </collision>
  </link>
  <joint
    name="controller_joint"
    type="fixed">
    <origin
      xyz="0.101379911991689 0.0620176418028498 0.00150000000000076"
      rpy="0 0 0" />
    <parent
      link="base_link" />
    <child
      link="controller_link" />
    <axis
      xyz="0 0 0" />
  </joint>
</robot>
