<?xml version="1.0" encoding="utf-8"?>
<!-- This URDF was automatically created by SolidWorks to URDF Exporter! Originally created by Stephen Brawner (brawner@gmail.com) 
     Commit Version: 1.6.0-4-g7f85cfe  Build Version: 1.6.7995.38578
     For more information, please see http://wiki.ros.org/sw_urdf_exporter -->
<robot
  name="top_mec_bs_robot">
  <link
    name="base_link">
    <inertial>
      <origin
        xyz="-0.00264136115542805 -0.000478714215745704 0.0465081194028082"
        rpy="0 0 0" />
      <mass
        value="4.86878291717535" />
      <inertia
        ixx="0.037251697324237"
        ixy="-4.62534191163563E-05"
        ixz="2.55824100252923E-08"
        iyy="0.0356401227216898"
        iyz="-5.69404839174868E-07"
        izz="0.0712831173052379" />
    </inertial>
    <visual>
      <origin
        xyz="0 0 0"
        rpy="0 0 0" />
      <geometry>
        <mesh
          filename="package://wheeltec_robot_urdf/meshes/top_mec_bs_robot_meshes/base_link.STL" />
      </geometry>
      <material
        name="">
        <color
          rgba="0.741176470588235 0.901960784313726 0.956862745098039 1" />
      </material>
    </visual>
    <collision>
      <origin
        xyz="0 0 0"
        rpy="0 0 0" />
      <geometry>
        <mesh
          filename="package://wheeltec_robot_urdf/meshes/top_mec_bs_robot_meshes/base_link.STL" />
      </geometry>
    </collision>
  </link>
  <link
    name="lf_wheel_link">
    <inertial>
      <origin
        xyz="1.97034659690232E-05 -0.00238148433606722 -4.49547036794617E-06"
        rpy="0 0 0" />
      <mass
        value="0.241686926461965" />
      <inertia
        ixx="0.000456944123565094"
        ixy="-1.84200464171476E-07"
        ixz="1.62222920669159E-08"
        iyy="0.000867978794635428"
        iyz="2.50176401996288E-09"
        izz="0.000456349229369202" />
    </inertial>
    <visual>
      <origin
        xyz="0 0 0"
        rpy="0 0 0" />
      <geometry>
        <mesh
          filename="package://wheeltec_robot_urdf/meshes/top_mec_bs_robot_meshes/lf_wheel_link.STL" />
      </geometry>
      <material
        name="">
        <color
          rgba="1 1 1 1" />
      </material>
    </visual>
    <collision>
      <origin
        xyz="0 0 0"
        rpy="0 0 0" />
      <geometry>
        <mesh
          filename="package://wheeltec_robot_urdf/meshes/top_mec_bs_robot_meshes/lf_wheel_link.STL" />
      </geometry>
    </collision>
  </link>
  <joint
    name="lf_wheel_joint"
    type="continuous">
    <origin
      xyz="0.307993160645862 0.311475641802979 0.022506"
      rpy="0 0 0" />
    <parent
      link="base_link" />
    <child
      link="lf_wheel_link" />
    <axis
      xyz="0 -1 0" />
  </joint>
  <link
    name="lb_wheel_link">
    <inertial>
      <origin
        xyz="1.97034680050612E-05 -0.00238148433616886 -4.49547096865316E-06"
        rpy="0 0 0" />
      <mass
        value="0.241686926457917" />
      <inertia
        ixx="0.00045694412355823"
        ixy="-1.84200458610283E-07"
        ixz="1.62222964552424E-08"
        iyy="0.000867978794626423"
        iyz="2.50176671642074E-09"
        izz="0.000456349229364437" />
    </inertial>
    <visual>
      <origin
        xyz="0 0 0"
        rpy="0 0 0" />
      <geometry>
        <mesh
          filename="package://wheeltec_robot_urdf/meshes/top_mec_bs_robot_meshes/lb_wheel_link.STL" />
      </geometry>
      <material
        name="">
        <color
          rgba="1 1 1 1" />
      </material>
    </visual>
    <collision>
      <origin
        xyz="0 0 0"
        rpy="0 0 0" />
      <geometry>
        <mesh
          filename="package://wheeltec_robot_urdf/meshes/top_mec_bs_robot_meshes/lb_wheel_link.STL" />
      </geometry>
    </collision>
  </link>
  <joint
    name="lb_wheel_joint"
    type="continuous">
    <origin
      xyz="-0.304006839354138 0.311475641802977 0.022506"
      rpy="0 0 0" />
    <parent
      link="base_link" />
    <child
      link="lb_wheel_link" />
    <axis
      xyz="0 -1 0" />
  </joint>
  <link
    name="rb_wheel_link">
    <inertial>
      <origin
        xyz="-1.97034706787558E-05 0.00238148433583746 -4.49547036781434E-06"
        rpy="0 0 0" />
      <mass
        value="0.241686926461961" />
      <inertia
        ixx="0.000456944123565086"
        ixy="-1.84200460735969E-07"
        ixz="-1.62222920674726E-08"
        iyy="0.000867978794635423"
        iyz="-2.50176401974032E-09"
        izz="0.000456349229369198" />
    </inertial>
    <visual>
      <origin
        xyz="0 0 0"
        rpy="0 0 0" />
      <geometry>
        <mesh
          filename="package://wheeltec_robot_urdf/meshes/top_mec_bs_robot_meshes/rb_wheel_link.STL" />
      </geometry>
      <material
        name="">
        <color
          rgba="1 1 1 1" />
      </material>
    </visual>
    <collision>
      <origin
        xyz="0 0 0"
        rpy="0 0 0" />
      <geometry>
        <mesh
          filename="package://wheeltec_robot_urdf/meshes/top_mec_bs_robot_meshes/rb_wheel_link.STL" />
      </geometry>
    </collision>
  </link>
  <joint
    name="rb_wheel_joint"
    type="continuous">
    <origin
      xyz="-0.304006839354135 -0.311440358197023 0.022506"
      rpy="0 0 0" />
    <parent
      link="base_link" />
    <child
      link="rb_wheel_link" />
    <axis
      xyz="0 1 0" />
  </joint>
  <link
    name="rf_wheel_link">
    <inertial>
      <origin
        xyz="-1.97034681442831E-05 0.00238148433552604 -4.49547021818403E-06"
        rpy="0 0 0" />
      <mass
        value="0.241686926462972" />
      <inertia
        ixx="0.000456944123566789"
        ixy="-1.84200464683279E-07"
        ixz="-1.62222909852801E-08"
        iyy="0.000867978794637645"
        iyz="-2.50176336124332E-09"
        izz="0.000456349229370351" />
    </inertial>
    <visual>
      <origin
        xyz="0 0 0"
        rpy="0 0 0" />
      <geometry>
        <mesh
          filename="package://wheeltec_robot_urdf/meshes/top_mec_bs_robot_meshes/rf_wheel_link.STL" />
      </geometry>
      <material
        name="">
        <color
          rgba="1 1 1 1" />
      </material>
    </visual>
    <collision>
      <origin
        xyz="0 0 0"
        rpy="0 0 0" />
      <geometry>
        <mesh
          filename="package://wheeltec_robot_urdf/meshes/top_mec_bs_robot_meshes/rf_wheel_link.STL" />
      </geometry>
    </collision>
  </link>
  <joint
    name="rf_wheel_joint"
    type="continuous">
    <origin
      xyz="0.307993160645865 -0.311440358197021 0.022506"
      rpy="0 0 0" />
    <parent
      link="base_link" />
    <child
      link="rf_wheel_link" />
    <axis
      xyz="0 1 0" />
  </joint>
  <link
    name="laser_link">
    <inertial>
      <origin
        xyz="0.00196458631115937 -3.57895338318423E-06 -0.000201831632144329"
        rpy="0 0 0" />
      <mass
        value="0.0477519163695691" />
      <inertia
        ixx="3.38461999733358E-05"
        ixy="-2.1989701325991E-09"
        ixz="1.07118468706629E-06"
        iyy="3.94150415850317E-05"
        iyz="6.8397864259877E-10"
        izz="5.6078704209586E-05" />
    </inertial>
    <visual>
      <origin
        xyz="0 0 0"
        rpy="0 0 0" />
      <geometry>
        <mesh
          filename="package://wheeltec_robot_urdf/meshes/top_mec_bs_robot_meshes/laser.STL" />
      </geometry>
      <material
        name="">
        <color
          rgba="0.376470588235294 0.376470588235294 0.376470588235294 1" />
      </material>
    </visual>
    <collision>
      <origin
        xyz="0 0 0"
        rpy="0 0 0" />
      <geometry>
        <mesh
          filename="package://wheeltec_robot_urdf/meshes/top_mec_bs_robot_meshes/laser.STL" />
      </geometry>
    </collision>
  </link>
  <joint
    name="laser_joint"
    type="fixed">
    <origin
      xyz="0.138557024250412 1.7991757980874E-05 0.126524183741431"
      rpy="0 0 -3.14159265358979" />
    <parent
      link="base_link" />
    <child
      link="laser_link" />
    <axis
      xyz="0 0 0" />
  </joint>
  <link
    name="camera_link">
    <inertial>
      <origin
        xyz="-4.4690477610243E-07 -3.53613893195584E-07 1.07624234465392E-07"
        rpy="0 0 0" />
      <mass
        value="0.055984251208029" />
      <inertia
        ixx="0.000130810959339212"
        ixy="1.20255128208263E-07"
        ixz="1.62335437080019E-06"
        iyy="1.91148634967938E-05"
        iyz="-2.80016755798322E-08"
        izz="0.00013138746952303" />
    </inertial>
    <visual>
      <origin
        xyz="0 0 0"
        rpy="0 0 0" />
      <geometry>
        <mesh
          filename="package://wheeltec_robot_urdf/meshes/top_mec_bs_robot_meshes/camera_link.STL" />
      </geometry>
      <material
        name="">
        <color
          rgba="1 1 1 1" />
      </material>
    </visual>
    <collision>
      <origin
        xyz="0 0 0"
        rpy="0 0 0" />
      <geometry>
        <mesh
          filename="package://wheeltec_robot_urdf/meshes/top_mec_bs_robot_meshes/camera_link.STL" />
      </geometry>
    </collision>
  </link>
  <joint
    name="camera_joint"
    type="fixed">
    <origin
      xyz="0.208902160645864 0.000245641802979065 0.108204"
      rpy="0 0 0" />
    <parent
      link="base_link" />
    <child
      link="camera_link" />
    <axis
      xyz="0 0 0" />
  </joint>
  <link
    name="controller_link">
    <inertial>
      <origin
        xyz="-0.049710340054785 0.0175133932690655 0.00856001464881972"
        rpy="0 0 0" />
      <mass
        value="0.00107921954114688" />
      <inertia
        ixx="1.1633010999567E-08"
        ixy="-3.94092662514923E-09"
        ixz="3.6921298272065E-10"
        iyy="2.26830021861902E-07"
        iyz="5.23015112125968E-10"
        izz="2.25657044103404E-07" />
    </inertial>
    <visual>
      <origin
        xyz="0 0 0"
        rpy="0 0 0" />
      <geometry>
        <mesh
          filename="package://wheeltec_robot_urdf/meshes/top_mec_bs_robot_meshes/controller_link.STL" />
      </geometry>
      <material
        name="">
        <color
          rgba="0.741176470588235 0.901960784313726 0.956862745098039 1" />
      </material>
    </visual>
    <collision>
      <origin
        xyz="0 0 0"
        rpy="0 0 0" />
      <geometry>
        <mesh
          filename="package://wheeltec_robot_urdf/meshes/top_mec_bs_robot_meshes/controller_link.STL" />
      </geometry>
    </collision>
  </link>
  <joint
    name="controller_joint"
    type="fixed">
    <origin
      xyz="0.101379911991696 0.0620176418028593 0.00150000000000075"
      rpy="0 0 0" />
    <parent
      link="base_link" />
    <child
      link="controller_link" />
    <axis
      xyz="0 0 0" />
  </joint>
</robot>
